Traceback (most recent call last):
  File "/Users/ea47/Documents/GitPages/dbms/.venv/lib/python3.13/site-packages/jupyter_cache/executors/utils.py", line 58, in single_nb_execution
    executenb(
    ~~~~~~~~~^
        nb,
        ^^^
    ...<4 lines>...
        **kwargs,
        ^^^^^^^^^
    )
    ^
  File "/Users/ea47/Documents/GitPages/dbms/.venv/lib/python3.13/site-packages/nbclient/client.py", line 1319, in execute
    return NotebookClient(nb=nb, resources=resources, km=km, **kwargs).execute()
           ~~~~~~~~~~~~~~~~~~~~~~~~~~~~~~~~~~~~~~~~~~~~~~~~~~~~~~~~~~~~~~~~~~~^^
  File "/Users/ea47/Documents/GitPages/dbms/.venv/lib/python3.13/site-packages/jupyter_core/utils/__init__.py", line 165, in wrapped
    return loop.run_until_complete(inner)
           ~~~~~~~~~~~~~~~~~~~~~~~^^^^^^^
  File "/opt/homebrew/Cellar/python@3.13/3.13.3/Frameworks/Python.framework/Versions/3.13/lib/python3.13/asyncio/base_events.py", line 719, in run_until_complete
    return future.result()
           ~~~~~~~~~~~~~^^
  File "/Users/ea47/Documents/GitPages/dbms/.venv/lib/python3.13/site-packages/nbclient/client.py", line 709, in async_execute
    await self.async_execute_cell(
        cell, index, execution_count=self.code_cells_executed + 1
    )
  File "/Users/ea47/Documents/GitPages/dbms/.venv/lib/python3.13/site-packages/nbclient/client.py", line 1062, in async_execute_cell
    await self._check_raise_for_error(cell, cell_index, exec_reply)
  File "/Users/ea47/Documents/GitPages/dbms/.venv/lib/python3.13/site-packages/nbclient/client.py", line 918, in _check_raise_for_error
    raise CellExecutionError.from_cell_and_msg(cell, exec_reply_content)
nbclient.exceptions.CellExecutionError: An error occurred while executing the following cell:
------------------
conn1 = sqlite3.connect("acid_demo.db", isolation_level="DEFERRED")
conn2 = sqlite3.connect("acid_demo.db", isolation_level="DEFERRED")

c1 = conn1.cursor()
c2 = conn2.cursor()

c1.execute("BEGIN")
c1.execute("UPDATE accounts SET balance = balance - 30 WHERE name = 'Alice'")

c2.execute("BEGIN")
try:
    c2.execute("UPDATE accounts SET balance = balance + 30 WHERE name = 'Bob'")
    conn2.commit()
except Exception as e:
    print("Isolation error:", e)

conn1.commit()

cursor = conn.cursor()
cursor.execute("SELECT * FROM accounts")
cursor.fetchall()

------------------


[31m---------------------------------------------------------------------------[39m
[31mOperationalError[39m                          Traceback (most recent call last)
[36mCell[39m[36m [39m[32mIn[4][39m[32m, line 8[39m
[32m      5[39m c2 = conn2.cursor()
[32m      7[39m c1.execute([33m"[39m[33mBEGIN[39m[33m"[39m)
[32m----> [39m[32m8[39m [43mc1[49m[43m.[49m[43mexecute[49m[43m([49m[33;43m"[39;49m[33;43mUPDATE accounts SET balance = balance - 30 WHERE name = [39;49m[33;43m'[39;49m[33;43mAlice[39;49m[33;43m'[39;49m[33;43m"[39;49m[43m)[49m
[32m     10[39m c2.execute([33m"[39m[33mBEGIN[39m[33m"[39m)
[32m     11[39m [38;5;28;01mtry[39;00m:

[31mOperationalError[39m: no such table: accounts

